<?xml version="1.0"?>
<robot xmlns:xacro="http://www.ros.org/wiki/xacro">

    <xacro:include filename="inertial_macros.xacro"/>

    <!-- <xacro:include filename="lidar.xacro"/> -->
    
    <material name="white">
        <color rgba="1 1 1 1" />
    </material>

    <material name="orange">
        <color rgba="1 0.3 0.1 1"/>
    </material>

    <material name="blue">
        <color rgba="0.2 0.2 1 1"/>
    </material>

    <material name="black">
        <color rgba="0 0 0 1"/>
    </material>

    <material name="red">
        <color rgba="1 0 0 1"/>
    </material>


    <!-- BASE LINK -->
    
    <link name="base_link">
    </link>

    <!-- BASE FOOTRPRINT LINK-->

    <joint name="base_footprint_joint" type="fixed">
        <parent link="base_link"/>
        <child link="base_footprint_link"/>
        <origin xyz="0.0 0.0 0.0"/>
    </joint>

    <link name="base_footprint_link">
    </link>

    <!-- CHASSIS LINK -->

    <joint name="chassis_joint" type="fixed">
        <parent link="base_link"/>
        <child link="chassis"/>
        <origin xyz="0.0 0.0 0.15"/>
    </joint>

    <link name="chassis">
        <visual>
            <origin xyz="0.0 0.0 0.0"/>
            <geometry>
                <box size="0.7 0.6 0.1"/>
            </geometry>
            <material name="red"/>
        </visual>
        <collision>
            <origin xyz="0.0 0.0 0.0"/>
            <geometry>
                <box size="0.7 0.6 0.1"/>
            </geometry>
        </collision>
        <xacro:inertial_box mass="5" x="0.7" y="0.6" z="0.1">
                <origin xyz="0.0 0.0 0.0" rpy="0.0 0.0 0.0"/>
        </xacro:inertial_box>
    </link>

       <!-- All Wheel links and joints -->
    <xacro:macro name="wheel" params="name x y z">
        <joint name="${name}_wheel_joint" type="continuous">
            <origin xyz="${x} ${y} ${z}" rpy="-${pi/2} 0.0 0.0"/>
            <parent link="chassis"/>
            <child link="${name}_wheel"/>
            <limit effort="1000.0" velocity="5.0"/>
            <axis xyz="0.0 0.0 1"/>
        </joint>

        <link name="${name}_wheel">
            <visual name="">
                <origin xyz="0.0 0.0 0.0" rpy="0.0 0.0 0.0"/>
                <geometry>
                    <cylinder radius="0.1" length="0.05"/>
                </geometry>
                <material name="white">
                    <color rgba="1.0 1.0 0.0 1.0"/>
                </material>
            </visual>
            <collision>
                <origin xyz="0.0 0.0 0.0" rpy="0.0 0.0 0.0"/>
                <geometry>
                    <cylinder radius="0.1" length="0.05"/>
                </geometry>
            </collision>
            <xacro:inertial_cylinder mass="0.75" length="0.05" radius="0.1">
                <origin xyz="0.0 0.0 0.0" rpy="0.0 0.0 0.0"/>
            </xacro:inertial_cylinder>
        </link>
    </xacro:macro>

    <!-- Wheel Creating using macros -->
    <xacro:wheel name="front_left"  x="0.250" y ="0.325" z="-0.055"/>
    <xacro:wheel name="rear_left" x="-0.250" y ="0.325" z="-0.055"/>
    <xacro:wheel name="front_right"  x="0.250" y ="-0.325" z="-0.055"/>
    <xacro:wheel name="rear_right"   x="-0.250" y ="-0.325" z="-0.055"/>

</robot>